Workbook

Sheet EFE-RCY
A3: WITHDRAWAL REQUEST FORM
A5: DELIVERY TO: | I5: UBOT D.R. NO:
A6: ANALOG DEVICES GEN. TRIAS INC | G6: DSGC WR NO: | H6: WRF-RCY-260341_ADGT
A7: SANDOVAL ST., GATEWAY BUSINESS PARK | G7: REQUESTED WITHDRAWAL DATE: | H7: 46280
A8: JAVALERA, GEN. TRIAS, CAVITE
A10: ITEM NO. | B10: QTY | C10: SPQ | D10: NO. OF BOXES | E10: CUST PN | F10: ITEM DESCRIPTION | G10: PO NUMBER | H10: BUSINESS UNIT | I10: EST. DISPATCH TIME
A11: 1 | C11: =IFERROR(VLOOKUP(E11,'DO NOT EDIT'!$B$2:$D$1007, 3, FALSE), "") -> 9000 | D11: =B11/C11 -> 0 | E11: 82011RM116M | F11: =IFERROR(VLOOKUP(E11, 'DO NOT EDIT'!$B$2:$D$1010, 2, FALSE), "") -> TUBE ASSY M_ADI-0098-22RT MSOP UP_DS | G11: 47304931 | H11: RCY | I11: 0.45833333
A12: 1 | B12: 10000 | C12: =IFERROR(VLOOKUP(E12,'DO NOT EDIT'!$B$2:$D$1007, 3, FALSE), "") -> 2000 | D12: =B12/C12 -> 5 | E12: 82011RU304M | F12: =IFERROR(VLOOKUP(E12, 'DO NOT EDIT'!$B$2:$D$1010, 2, FALSE), "") -> TUBE ASSY M_ADI-0098-23RT 14-16 ARWUP_D | G12: 47367069 | H12: RCY | I12: 0.45833333
A13: 2 | B13: 9000 | C13: =IFERROR(VLOOKUP(E13,'DO NOT EDIT'!$B$2:$D$1007, 3, FALSE), "") -> 9000 | D13: =B13/C13 -> 1 | E13: 82011RM117M | F13: =IFERROR(VLOOKUP(E13, 'DO NOT EDIT'!$B$2:$D$1010, 2, FALSE), "") -> TUBE ASSY M_ADI-0098-22RT MSOP DWN_DS | G13: 47367069 | H13: RCY | I13: 0.45833333
A14: 3 | B14: 9000 | C14: =IFERROR(VLOOKUP(E14,'DO NOT EDIT'!$B$2:$D$1007, 3, FALSE), "") -> 9000 | D14: =B14/C14 -> 1 | E14: 82011RM117M | F14: =IFERROR(VLOOKUP(E14, 'DO NOT EDIT'!$B$2:$D$1010, 2, FALSE), "") -> TUBE ASSY M_ADI-0098-22RT MSOP DWN_DS | G14: 47386150 | H14: RCY | I14: 0.45833333
A15: 4 | B15: 3000 | C15: =IFERROR(VLOOKUP(E15,'DO NOT EDIT'!$B$2:$D$1007, 3, FALSE), "") -> 1000 | D15: =B15/C15 -> 3 | E15: 82011RS219M | F15: =IFERROR(VLOOKUP(E15, 'DO NOT EDIT'!$B$2:$D$1010, 2, FALSE), "") -> TUBE ASSY M_ADI-0098-24RT 5.3MM SSOP UP_D | G15: 47386150 | H15: RCY | I15: 0.45833333
A16: 5 | B16: 4500 | C16: =IFERROR(VLOOKUP(E16,'DO NOT EDIT'!$B$2:$D$1007, 3, FALSE), "") -> 4500 | D16: =B16/C16 -> 1 | E16: 82011RM113M | F16: =IFERROR(VLOOKUP(E16, 'DO NOT EDIT'!$B$2:$D$1010, 2, FALSE), "") -> TUBE ASSY M_LT-001RT MSOP DWN LTC_D | G16: 47386150 | H16: RCY | I16: 0.45833333
A17: 6 | B17: 1800 | C17: =IFERROR(VLOOKUP(E17,'DO NOT EDIT'!$B$2:$D$1007, 3, FALSE), "") -> 600 | D17: =B17/C17 -> 3 | E17: 820110R215M | F17: =IFERROR(VLOOKUP(E17, 'DO NOT EDIT'!$B$2:$D$1010, 2, FALSE), "") -> TUBE ASSY M_LT-003RT SOIC/SSOP DWN LTC_D | G17: 47386150 | H17: RCY | I17: 0.45833333
A18: 7 | B18: 5000 | C18: =IFERROR(VLOOKUP(E18,'DO NOT EDIT'!$B$2:$D$1007, 3, FALSE), "") -> 5000 | D18: =B18/C18 -> 1 | E18: 82011CP279M | F18: =IFERROR(VLOOKUP(E18, 'DO NOT EDIT'!$B$2:$D$1010, 2, FALSE), "") -> TUBE ASSY M_LT-004RT 3X3 QFN UP LTC_D | G18: 47386150 | H18: RCY | I18: 0.45833333
A19: 8 | B19: 14000 | C19: =IFERROR(VLOOKUP(E19,'DO NOT EDIT'!$B$2:$D$1007, 3, FALSE), "") -> 2000 | D19: =B19/C19 -> 7 | E19: 82011RU305M | F19: =IFERROR(VLOOKUP(E19, 'DO NOT EDIT'!$B$2:$D$1010, 2, FALSE), "") -> TUBE ASSY M_ADI-0098-23RT 14-16 ARWDN_D | G19: 47359805 | H19: RCY | I19: 0.45833333
A20: 9 | B20: 13500 | C20: =IFERROR(VLOOKUP(E20,'DO NOT EDIT'!$B$2:$D$1007, 3, FALSE), "") -> 4500 | D20: =B20/C20 -> 3 | E20: 82011RM112M | F20: =IFERROR(VLOOKUP(E20, 'DO NOT EDIT'!$B$2:$D$1010, 2, FALSE), "") -> TUBE ASSY M_LT-001RT MSOP UP LTC_D | G20: 47359805 | H20: RCY | I20: 0.45833333
A21: 10 | B21: 2000 | C21: =IFERROR(VLOOKUP(E21,'DO NOT EDIT'!$B$2:$D$1007, 3, FALSE), "") -> 2000 | D21: =B21/C21 -> 1 | E21: 82011RU307M | F21: =IFERROR(VLOOKUP(E21, 'DO NOT EDIT'!$B$2:$D$1010, 2, FALSE), "") -> TUBE ASSY M_ADI-0098-27RT 8L ARRDWN_DS | G21: 47304931 | H21: RCY | I21: 0.45833333
A22: 11 | B22: 27000 | C22: =IFERROR(VLOOKUP(E22,'DO NOT EDIT'!$B$2:$D$1007, 3, FALSE), "") -> 4500 | D22: =B22/C22 -> 6 | E22: 82011RM120M | F22: =IFERROR(VLOOKUP(E22, 'DO NOT EDIT'!$B$2:$D$1010, 2, FALSE), "") -> TUBE ASSY M_LT-001RT MSOP NOPLUG_D | G22: 47364201 | H22: RCY | I22: 0.45833333
A23: 12 | B23: 25000 | C23: =IFERROR(VLOOKUP(E23,'DO NOT EDIT'!$B$2:$D$1007, 3, FALSE), "") -> 5000 | D23: =B23/C23 -> 5 | E23: 82011CP280M | F23: =IFERROR(VLOOKUP(E23, 'DO NOT EDIT'!$B$2:$D$1010, 2, FALSE), "") -> TUBE ASSY M_LT-004RT 3X3 QFN DWN LTC_D | G23: 47369982 | H23: RCY | I23: 0.45833333
... A26: 15 | B26: 1050 | C26: =IFERROR(VLOOKUP(E26,'DO NOT EDIT'!$B$2:$D$1007, 3, FALSE), "") -> 150 | D26: =B26/C26 -> 7 | E26: 82011VR007 | F26: =IFERROR(VLOOKUP(E26, 'DO NOT EDIT'!$B$2:$D$1010, 2, FALSE), "") -> TUBE ASSY C_LT016RT DDPAK NOPLG LTC_D | G26: 47303686 | H26: RCY | I26: 0.45833333
A27: N/F | B27: N/F | C27: N/F | D27: N/F | E27: N/F | F27: N/F | G27: N/F | H27: N/F | I27: N/F
D29: =SUM(D11:D26) -> 47
A30: Total QTY | D30: =SUM(B11:B26) -> 136850
A32: DELIVERY INSTRUCTIONS/REMARKS:
A35: R.Portes
A36: CSR
H38: PRO-CS-068 Form A. Rev. 01
I39: EFF. DATE: 08 JAN. 2024

Sheet DO NOT EDIT
A1: DO NOT EDIT THIS SHEET.
A2: NO. | B2: ITEM CODE | C2: DESCRIPTION | D2: SPQ
A3: 1 | B3: 820110R208 | C3: TUBE ASSY C_ADI-0098-10RT 8L ARROW UP_DS | D3: 1500
A4: 2 | B4: 820110R208M | C4: TUBE ASSY M_ADI-0098-10RT 8L ARROW UP_DS | D4: 1500
A5: 3 | B5: 820110R209 | C5: TUBE ASSY C_ADI-0098-10RT 8L ARW DWN_DS | D5: 1500
A6: 4 | B6: 820110R209M | C6: TUBE ASSY M_ADI-0098-10RT 8L ARW DWN_DS | D6: 1500
A7: 5 | B7: 820110R218 | C7: TUBE ASSY C_ADI-0098-10HV 8L ARROW UP_D | D7: 1500
A8: 6 | B8: 820110R218M | C8: TUBE ASSY M_ADI-0098-10HV 8L ARROW UP_D | D8: 1500
A9: 7 | B9: 820110R219 | C9: TUBE ASSY C_ADI-0098-10HV 8L ARW DWN_D | D9: 1500
A10: 8 | B10: 820110R219M | C10: TUBE ASSY M_ADI-0098-10HV 8L ARW DWN_D | D10: 1500
A11: 9 | B11: 820110R220 | C11: TUBE ASSY C_ADI-0098-12HV 8L ARROW UP_D | D11: 600
A12: 10 | B12: 820110R220M | C12: TUBE ASSY M_ADI-0098-12HV 8L ARROW UP_D | D12: 600
A13: 11 | B13: 820110R221 | C13: TUBE ASSY C_ADI-0098-12HV 8L ARW DWN_D | D13: 600
A14: 12 | B14: 820110R221M | C14: TUBE ASSY M_ADI-0098-12HV 8L ARW DWN_D | D14: 600
... A119: 118 | B119: 82011VR007M | C119: TUBE ASSY M_LT016RT DDPAK NOPLG LTC_D | D119: 150
A120: 119 | B120: 820110P448 | C120: TUBE ASSY C_ADI-0098-05RT 20L PLCC UP_D
A121: 120 | B121: 820110P448M | C121: TUBE ASSY M_ADI-0098-05RT 20L PLCC UP_D
A122: 121 | B122: 820110P449 | C122: TUBE ASSY C_ADI-0098-05RT 20L PLCC DWN_D
A123: 122 | B123: 820110P449M | C123: TUBE ASSY M_ADI-0098-05RT 20L PLCC DWN_D
A124: 123 | B124: 820110P450 | C124: TUBE ASSY C_ADI-0098-06RT 28L PLCC UP_D
A125: 124 | B125: 820110P450M | C125: TUBE ASSY M_ADI-0098-06RT 28L PLCC UP_D
A126: 125 | B126: 820110E455 | C126: TUBE ASSY C_ADI-0098-13RT 20L LCC DWN_D
A127: 126 | B127: 820110E455M | C127: TUBE ASSY M_ADI-0098-13RT 20L LCC DWN_D
A128: 127 | B128: 820110E456 | C128: TUBE ASSY C_ADI-0098-14RT 28L LCC UP_D
A129: 128 | B129: 820110E456M | C129: TUBE ASSY M_ADI-0098-14RT 28L LCC UP_D
A130: 129 | B130: 820110E457 | C130: TUBE ASSY C_ADI-0098-14RT 28L LCC DWN_D
A131: 130 | B131: 820110E457M | C131: TUBE ASSY M_ADI-0098-14RT 28L LCC DWN_D
... A163: 162 | B163: 820110N258 | C163: TUBE ASSY C_ADI-0098-34RT 300PDIP DWN_D
A164: 163 | B164: 82011RU306 | C164: TUBE ASSY C_ADI-0098-27RT 8L ARROWUP_DS | D164: 2000
A165: 164 | B165: 82011RU306M | C165: TUBE ASSY M_ADI-0098-27RT 8L ARROWUP_DS | D165: 2000
A166: 165 | B166: 82011RU307 | C166: TUBE ASSY C_ADI-0098-27RT 8L ARRWDWN_DS | D166: 2000
A167: 166 | B167: 82011RU307M | C167: TUBE ASSY M_ADI-0098-27RT 8L ARRDWN_DS | D167: 2000
A168: 167 | B168: 82011RU308 | C168: TUBE ASSY C_ADI-0098-29RT 28-48 ARWUP_D
A169: 168 | B169: 82011RU308M | C169: TUBE ASSY M_ADI-0098-29RT 28-48 ARWUP_D
A170: 169 | B170: 82011RU309 | C170: TUBE ASSY C_ADI-0098-29RT 28-48 ARWDN_D
A171: 170 | B171: 82011RU309M | C171: TUBE ASSY M_ADI-0098-29RT 28-48 ARWDN_D
A172: 171 | B172: 8020405002T | C172: Black Box Cleaning- 375mmX178mmX82mm | D172: 50
A173: 172 | B173: 820110R216M | C173: TUBE ASSY M_ADI-0098-35RT SOIC CAV UP_D | D173: 600
A174: 174 | B174: 820110R217M | C174: TUBE ASSY M_ADI-0098-35RTSOIC CAV DWN_D | D174: 600
A175: 175 | B175: 820110R217 | C175: TUBE ASSY C_ADI-0098-35RTSOIC CAV DWN_D | D175: 600
...
